Workbook

Sheet DASHBOARD
C1: Total of hours | D1: % Positive Mock Tests | E1: Can I book my test?
C2: =SUM(B14:B17) -> 0 | D2: ='MOCK TESTS'!G1 -> #DIV/0! | E2: =if(D2>70%, "Yes", "Not yet") -> #DIV/0!
A5: Phase 01 - Preparation | B5: What you have to do | D5: English Levels
A6: Week 1 | B6: Watch the most important class of the course | D6: 90 hours: probably A1
B7: Watch the module 1 | D7: 180 hours: probably A2
A8: Week 2 | B8: Watch the module 2 | D8: 350 hours: probably B1
A9: Week 3 | B9: Watch the modules 3 and 4 | D9: 600 hours: probably B2
A10: Week 4 | B10: Watch the modules 5 and 6 | D10: 900 hours: probably C1
D11: above 1800 hours: probably C2
A13: Phase 02 - Execution | B13: Status | D13: Current level
A14: Listening | B14: =LISTENING!D2 -> 0 | D14: =IF(C2 = 0, "Not started", IF(C2 < 90, "Beginner", IF(AND(C2 >= 90, C2 <= 179.9), "A1", IF(AND(C2 >= 180, C2 <= 349.9), "A2", IF(AND(C2 >= 350, C2 <= 599.9), "B1", IF(AND(C2 >= 600, C2 <= 899.9), "B2", IF(AND(C2 >= 900, C2 <= 1799.9), "C1", IF(C2 > 1799.9, "C2", "") ))))))) -> Not started
A15: Reading | B15: =READING!D2 -> 0
A16: Writing | B16: =WRITING!D2 -> 0
A17: Speaking | B17: =SPEAKING!D2 -> 0
A20: Phase 03 - Final sprint | B20: Mock Tests done
A21: 90 days to the test | B21: ='MOCK TESTS'!F538 -> 0
A22: 45 days to the test | B22: ='MOCK TESTS'!F548 -> 0
A23: 21 days to the test | B23: ='MOCK TESTS'!F556 -> 0
A24: 15 days to the test | B24: ='MOCK TESTS'!F562 -> 0
A27: ATTENTION:
A28: To use the spreadsheet, you DO NOT need to request access.
A29: You must make your copy (File > Make a copy)
A30: or download it (File > Download).
A31: This spreadsheet was designed for students only
A32: and cannot be shared without previous written permission.

Sheet LISTENING
A1: LISTENING RECORDS | B1: What did you do your exposure with? | C1: Exposure (minutes) | D1: Total of hours
D2: =SUM(C4:C521)/60 -> 0
A4: Week 1
A5: Day 1 | B5: Click to select
A6: Day 2 | B6: Click to select
A7: Day 3 | B7: Click to select
A8: Day 4 | B8: Click to select
A9: Day 5 | B9: Click to select
A10: Day 6 | B10: Click to select
A11: Day 7 | B11: Click to select
A14: Week 2
A15: Day 8 | B15: Click to select
A16: Day 9 | B16: Click to select
A17: Day 10 | B17: Click to select
A18: Day 11 | B18: Click to select
A19: Day 12 | B19: Click to select
A20: Day 13 | B20: Click to select
A21: Day 14 | B21: Click to select
A24: Week 3
A25: Day 15 | B25: Click to select
A26: Day 16 | B26: Click to select
A27: Day 17 | B27: Click to select
A28: Day 18 | B28: Click to select
A29: Day 19 | B29: Click to select
A30: Day 20 | B30: Click to select
A31: Day 21 | B31: Click to select
A34: Week 4
A35: Day 22 | B35: Click to select
A36: Day 23 | B36: Click to select
A37: Day 24 | B37: Click to select
A38: Day 25 | B38: Click to select
A39: Day 26 | B39: Click to select
A40: Day 27 | B40: Click to select
A41: Day 28 | B41: Click to select
A44: Week 5
A45: Day 29 | B45: Click to select
A46: Day 30 | B46: Click to select
A47: Day 31 | B47: Click to select
A48: Day 32 | B48: Click to select
A49: Day 33 | B49: Click to select
...

Sheet READING
A1: READING RECORDS | B1: What did you do your exposure with? | C1: Exposure (minutes) | D1: Total of hours
D2: =SUM(C4:C521)/60 -> 0
A4: Week 1
A5: Day 1 | B5: Click to select
A6: Day 2 | B6: Click to select
A7: Day 3 | B7: Click to select
A8: Day 4 | B8: Click to select
A9: Day 5 | B9: Click to select
A10: Day 6 | B10: Click to select
A11: Day 7 | B11: Click to select
A14: Week 2
A15: Day 8 | B15: Click to select
A16: Day 9 | B16: Click to select
A17: Day 10 | B17: Click to select
A18: Day 11 | B18: Click to select
A19: Day 12 | B19: Click to select
A20: Day 13 | B20: Click to select
A21: Day 14 | B21: Click to select
A24: Week 3
A25: Day 15 | B25: Click to select
A26: Day 16 | B26: Click to select
A27: Day 17 | B27: Click to select
A28: Day 18 | B28: Click to select
A29: Day 19 | B29: Click to select
A30: Day 20 | B30: Click to select
A31: Day 21 | B31: Click to select
A34: Week 4
A35: Day 22 | B35: Click to select
A36: Day 23 | B36: Click to select
A37: Day 24 | B37: Click to select
A38: Day 25 | B38: Click to select
A39: Day 26 | B39: Click to select
A40: Day 27 | B40: Click to select
A41: Day 28 | B41: Click to select
A44: Week 5
A45: Day 29 | B45: Click to select
A46: Day 30 | B46: Click to select
A47: Day 31 | B47: Click to select
A48: Day 32 | B48: Click to select
A49: Day 33 | B49: Click to select
...

Sheet WRITING
A1: WRITING RECORDS | B1: What did you do? | C1: Exposure (minutes) | D1: Total of hours
D2: =SUM(C4:C521)/60 -> 0
A4: Week 1
A5: Day 1 | B5: Click to select
A6: Day 2 | B6: Click to select
A7: Day 3 | B7: Click to select
A8: Day 4 | B8: Click to select
A9: Day 5 | B9: Click to select
A10: Day 6 | B10: Click to select
A11: Day 7 | B11: Click to select
A14: Week 2
A15: Day 8 | B15: Click to select
A16: Day 9 | B16: Click to select
A17: Day 10 | B17: Click to select
A18: Day 11 | B18: Click to select
A19: Day 12 | B19: Click to select
A20: Day 13 | B20: Click to select
A21: Day 14 | B21: Click to select
A24: Week 3
A25: Day 15 | B25: Click to select
A26: Day 16 | B26: Click to select
A27: Day 17 | B27: Click to select
A28: Day 18 | B28: Click to select
A29: Day 19 | B29: Click to select
A30: Day 20 | B30: Click to select
A31: Day 21 | B31: Click to select
A34: Week 4
A35: Day 22 | B35: Click to select
A36: Day 23 | B36: Click to select
A37: Day 24 | B37: Click to select
A38: Day 25 | B38: Click to select
A39: Day 26 | B39: Click to select
A40: Day 27 | B40: Click to select
A41: Day 28 | B41: Click to select
A44: Week 5
A45: Day 29 | B45: Click to select
A46: Day 30 | B46: Click to select
A47: Day 31 | B47: Click to select
A48: Day 32 | B48: Click to select
A49: Day 33 | B49: Click to select
...

Sheet SPEAKING
A1: SPEAKING RECORDS | B1: Whom did you do your training with? | C1: Exposure (minutes) | D1: Total of hours
D2: =SUM(C4:C521)/60 -> 0
A4: Week 1
A5: Day 1 | B5: Click to select
A6: Day 2 | B6: Click to select
A7: Day 3 | B7: Click to select
A8: Day 4 | B8: Click to select
A9: Day 5 | B9: Click to select
A10: Day 6 | B10: Click to select
A11: Day 7 | B11: Click to select
A14: Week 2
A15: Day 8 | B15: Click to select
A16: Day 9 | B16: Click to select
A17: Day 10 | B17: Click to select
A18: Day 11 | B18: Click to select
A19: Day 12 | B19: Click to select
A20: Day 13 | B20: Click to select
A21: Day 14 | B21: Click to select
A24: Week 3
A25: Day 15 | B25: Click to select
A26: Day 16 | B26: Click to select
A27: Day 17 | B27: Click to select
A28: Day 18 | B28: Click to select
A29: Day 19 | B29: Click to select
A30: Day 20 | B30: Click to select
A31: Day 21 | B31: Click to select
A34: Week 4
A35: Day 22 | B35: Click to select
A36: Day 23 | B36: Click to select
A37: Day 24 | B37: Click to select
A38: Day 25 | B38: Click to select
A39: Day 26 | B39: Click to select
A40: Day 27 | B40: Click to select
A41: Day 28 | B41: Click to select
A44: Week 5
A45: Day 29 | B45: Click to select
A46: Day 30 | B46: Click to select
A47: Day 31 | B47: Click to select
A48: Day 32 | B48: Click to select
A49: Day 33 | B49: Click to select
...

Sheet MOCK TESTS
A1: PHASE 03 FINAL SPRINT | B1: Mock tests done: | C1: =D562 -> 0 | D1: Positive Mock Tests: | E1: =D565 -> 0 | F1: Percentage of Positive Mock Tests: | G1: =D568 -> #DIV/0!
A5: 90 days to the test | B5: Took Mock Test? | C5: Listening Score | D5: Reading Score | E5: Writing Score | F5: Speaking Score | G5: Reached target score?
A6: Week 12 | B6: write 1 if you did | C6: Click to select | D6: Click to select | E6: Click to select | F6: Click to select | G6: Click to select
A7: Week 11 | B7: write 1 if you did | C7: Click to select | D7: Click to select | E7: Click to select | F7: Click to select | G7: Click to select
A8: Week 10 | B8: write 1 if you did | C8: Click to select | D8: Click to select | E8: Click to select | F8: Click to select | G8: Click to select
A9: Week 09 | B9: write 1 if you did | C9: Click to select | D9: Click to select | E9: Click to select | F9: Click to select | G9: Click to select
A10: Week 08 | B10: write 1 if you did | C10: Click to select | D10: Click to select | E10: Click to select | F10: Click to select | G10: Click to select
A11: Week 07 | B11: write 1 if you did | C11: Click to select | D11: Click to select | E11: Click to select | F11: Click to select | G11: Click to select
A12: Week 06 | B12: write 1 if you did | C12: Click to select | D12: Click to select | E12: Click to select | F12: Click to select | G12: Click to select
A15: 45 days to the test
A16: Week 05 - Mock Test 1 | B16: write 1 if you did | C16: Click to select | D16: Click to select | E16: Click to select | F16: Click to select | G16: Click to select
A17: Week 05 - Mock Test 2 | B17: write 1 if you did | C17: Click to select | D17: Click to select | E17: Click to select | F17: Click to select | G17: Click to select
A19: Week 04 - Mock Test 1 | B19: write 1 if you did | C19: Click to select | D19: Click to select | E19: Click to select | F19: Click to select | G19: Click to select
A20: Week 04 - Mock Test 2 | B20: write 1 if you did | C20: Click to select | D20: Click to select | E20: Click to select | F20: Click to select | G20: Click to select
A23: 21 days to the test
A24: Week 03 - Mock Test 1 | B24: write 1 if you did | C24: Click to select | D24: Click to select | E24: Click to select | F24: Click to select | G24: Click to select
A25: Week 03 - Mock Test 2 | B25: write 1 if you did | C25: Click to select | D25: Click to select | E25: Click to select | F25: Click to select | G25: Click to select
A26: Week 03 - Mock Test 3 | B26: write 1 if you did | C26: Click to select | D26: Click to select | E26: Click to select | F26: Click to select | G26: Click to select
A29: 15 days to the test
A30: Week 02 - Mock Test 1 | B30: write 1 if you did | C30: Click to select | D30: Click to select | E30: Click to select | F30: Click to select | G30: Click to select
A31: Week 02 - Mock test 2 | B31: write 1 if you did | C31: Click to select | D31: Click to select | E31: Click to select | F31: Click to select | G31: Click to select
A32: Week 02 - Mock test 3 | B32: write 1 if you did | C32: Click to select | D32: Click to select | E32: Click to select | F32: Click to select | G32: Click to select
A33: Week 02 - Mock test 4 | B33: write 1 if you did | C33: Click to select | D33: Click to select | E33: Click to select | F33: Click to select | G33: Click to select
A34: Week 02 - Mock test 5 | B34: write 1 if you did | C34: Click to select | D34: Click to select | E34: Click to select | F34: Click to select | G34: Click to select
A36: Week 01 - Mock test 1 | B36: write 1 if you did | C36: Click to select | D36: Click to select | E36: Click to select | F36: Click to select | G36: Click to select
A37: Week 01 - Mock test 2 | B37: write 1 if you did | C37: Click to select | D37: Click to select | E37: Click to select | F37: Click to select | G37: Click to select
A38: Week 01 - Mock test 3 | B38: write 1 if you did | C38: Click to select | D38: Click to select | E38: Click to select | F38: Click to select | G38: Click to select
A39: Week 01 - Mock test 4 | B39: write 1 if you did | C39: Click to select | D39: Click to select | E39: Click to select | F39: Click to select | G39: Click to select
A40: Week 01 - Mock test 5 | B40: write 1 if you did | C40: Click to select | D40: Click to select | E40: Click to select | F40: Click to select | G40: Click to select
D519: =if(G6="Yes", 1) -> FALSE
D520: =if(G7="Yes", 1) -> FALSE
D521: =if(G8="Yes", 1) -> FALSE
D522: =if(G9="Yes", 1) -> FALSE
D523: =if(G10="Yes", 1) -> FALSE
D524: =if(G11="Yes", 1) -> FALSE
D525: =if(G12="Yes", 1) -> FALSE
D529: =if(G16="Yes", 1) -> FALSE
D530: =if(G17="Yes", 1) -> FALSE
D532: =if(G19="Yes", 1) -> FALSE
D533: =if(G20="Yes", 1) -> FALSE
...
